<?xml version="1.0" encoding="utf-8"?>
<!-- This URDF was automatically created by SolidWorks to URDF Exporter! Originally created by Stephen Brawner (brawner@gmail.com) 
     Commit Version: 1.6.0-4-g7f85cfe  Build Version: 1.6.7995.38578
     For more information, please see http://wiki.ros.org/sw_urdf_exporter -->
<robot
  name="starlink_space_manipulator_merged.SLDASM9">
  <link
    name="starlink_space_manipulator_base_link">
    <inertial>
      <origin
        xyz="-0.00908719924946466 0.0225428225681148 -0.00851924929637313"
        rpy="0 0 0" />
      <mass
        value="8.66024015898073" />
      <inertia
        ixx="0.0960303512697639"
        ixy="1.65511904636803E-18"
        ixz="6.22039820639877E-19"
        iyy="0.103454922260914"
        iyz="-9.68471289978311E-19"
        izz="0.0960303512697639" />
    </inertial>
    <visual>
      <origin
        xyz="0 0 0"
        rpy="0 0 0" />
      <geometry>
        <mesh
          filename="package://starlink_space_manipulator_merged.SLDASM9/meshes/starlink_space_manipulator_base_link.STL" />
      </geometry>
      <material
        name="">
        <color
          rgba="0.792156862745098 0.819607843137255 0.933333333333333 1" />
      </material>
    </visual>
    <collision>
      <origin
        xyz="0 0 0"
        rpy="0 0 0" />
      <geometry>
        <mesh
          filename="package://starlink_space_manipulator_merged.SLDASM9/meshes/starlink_space_manipulator_base_link.STL" />
      </geometry>
    </collision>
  </link>
  <link
    name="starlink_space_manipulator_Shoulder_link_1">
    <inertial>
      <origin
        xyz="-0.000399471745595769 -0.100006574194712 -0.17423940484461"
        rpy="0 0 0" />
      <mass
        value="5.16309216784981" />
      <inertia
        ixx="0.0524543852135592"
        ixy="0.00348154867667969"
        ixz="6.96526910910627E-05"
        iyy="0.0306595326318824"
        iyz="-0.00056674368052247"
        izz="0.0439979075615329" />
    </inertial>
    <visual>
      <origin
        xyz="0 0 0"
        rpy="0 0 0" />
      <geometry>
        <mesh
          filename="package://starlink_space_manipulator_merged.SLDASM9/meshes/starlink_space_manipulator_Shoulder_link_1.STL" />
      </geometry>
      <material
        name="">
        <color
          rgba="0.792156862745098 0.819607843137255 0.933333333333333 1" />
      </material>
    </visual>
    <collision>
      <origin
        xyz="0 0 0"
        rpy="0 0 0" />
      <geometry>
        <mesh
          filename="package://starlink_space_manipulator_merged.SLDASM9/meshes/starlink_space_manipulator_Shoulder_link_1.STL" />
      </geometry>
    </collision>
  </link>
  <joint
    name="starlink_space_manipulator_Shoulder_link_1_yaw"
    type="revolute">
    <origin
      xyz="-0.0090872 -0.065 -0.0085192"
      rpy="1.5708 -0.15574 3.1416" />
    <parent
      link="starlink_space_manipulator_base_link" />
    <child
      link="starlink_space_manipulator_Shoulder_link_1" />
    <axis
      xyz="0 0 -1" />
    <limit
      lower="-3.14"
      upper="3.14"
      effort="0"
      velocity="0" />
  </joint>
  <link
    name="starlink_space_manipulator_Upper_arm_Link_1">
    <inertial>
      <origin
        xyz="0.402106341472203 -0.696465272634528 -0.170177523085579"
        rpy="0 0 0" />
      <mass
        value="5.05309869040685" />
      <inertia
        ixx="0.388719013133801"
        ixy="0.210155896498943"
        ixz="9.30829370680679E-08"
        iyy="0.146049057575642"
        iyz="1.71830458004218E-07"
        izz="0.500677708275447" />
    </inertial>
    <visual>
      <origin
        xyz="0 0 0"
        rpy="0 0 0" />
      <geometry>
        <mesh
          filename="package://starlink_space_manipulator_merged.SLDASM9/meshes/starlink_space_manipulator_Upper_arm_Link_1.STL" />
      </geometry>
      <material
        name="">
        <color
          rgba="0.792156862745098 0.819607843137255 0.933333333333333 1" />
      </material>
    </visual>
    <collision>
      <origin
        xyz="0 0 0"
        rpy="0 0 0" />
      <geometry>
        <mesh
          filename="package://starlink_space_manipulator_merged.SLDASM9/meshes/starlink_space_manipulator_Upper_arm_Link_1.STL" />
      </geometry>
    </collision>
  </link>
  <joint
    name="starlink_space_manipulator_Upper_arm_Link_1_roll"
    type="revolute">
    <origin
      xyz="0 -0.2 -0.18"
      rpy="1.5708 0.90646 1.5708" />
    <parent
      link="starlink_space_manipulator_Shoulder_link_1" />
    <child
      link="starlink_space_manipulator_Upper_arm_Link_1" />
    <axis
      xyz="0 0 -1" />
    <limit
      lower="-2"
      upper="1.5"
      effort="0"
      velocity="0" />
  </joint>
  <link
    name="starlink_space_manipulator_Mid_arm_Link_1">
    <inertial>
      <origin
        xyz="-0.000406052776441013 0.317722269561105 0.0155331755135703"
        rpy="0 0 0" />
      <mass
        value="1.57635531881168" />
      <inertia
        ixx="0.133610363618846"
        ixy="5.33750993405138E-05"
        ixz="-3.60473795202962E-09"
        iyy="0.00502119434334708"
        iyz="-2.514275749911E-05"
        izz="0.134586018527477" />
    </inertial>
    <visual>
      <origin
        xyz="0 0 0"
        rpy="0 0 0" />
      <geometry>
        <mesh
          filename="package://starlink_space_manipulator_merged.SLDASM9/meshes/starlink_space_manipulator_Mid_arm_Link_1.STL" />
      </geometry>
      <material
        name="">
        <color
          rgba="1 1 1 1" />
      </material>
    </visual>
    <collision>
      <origin
        xyz="0 0 0"
        rpy="0 0 0" />
      <geometry>
        <mesh
          filename="package://starlink_space_manipulator_merged.SLDASM9/meshes/starlink_space_manipulator_Mid_arm_Link_1.STL" />
      </geometry>
    </collision>
  </link>
  <joint
    name="starlink_space_manipulator_Mid_arm_Link_1_roll"
    type="revolute">
    <origin
      xyz="0.599999999999673 -1.03923048454122 0"
      rpy="-3.14159265358979 0 0.828250280535091" />
    <parent
      link="starlink_space_manipulator_Upper_arm_Link_1" />
    <child
      link="starlink_space_manipulator_Mid_arm_Link_1" />
    <axis
      xyz="0 0 -1" />
    <limit
      lower="-3.14"
      upper="3.14"
      effort="0"
      velocity="0" />
  </joint>
  <link
    name="starlink_space_manipulator_Upper_wrist_Link_1">
    <inertial>
      <origin
        xyz="-0.000400003664721815 -0.201565878030355 -0.00216705855311664"
        rpy="0 0 0" />
      <mass
        value="0.994770641034713" />
      <inertia
        ixx="0.00165409639029414"
        ixy="-7.59103925411082E-06"
        ixz="-3.17403155320863E-06"
        iyy="0.00201437937768072"
        iyz="2.63246464091218E-06"
        izz="0.00159638838344539" />
    </inertial>
    <visual>
      <origin
        xyz="0 0 0"
        rpy="0 0 0" />
      <geometry>
        <mesh
          filename="package://starlink_space_manipulator_merged.SLDASM9/meshes/starlink_space_manipulator_Upper_wrist_Link_1.STL" />
      </geometry>
      <material
        name="">
        <color
          rgba="0.792156862745098 0.819607843137255 0.933333333333333 1" />
      </material>
    </visual>
    <collision>
      <origin
        xyz="0 0 0"
        rpy="0 0 0" />
      <geometry>
        <mesh
          filename="package://starlink_space_manipulator_merged.SLDASM9/meshes/starlink_space_manipulator_Upper_wrist_Link_1.STL" />
      </geometry>
    </collision>
  </link>
  <joint
    name="starlink_space_manipulator_Upper_wrist_Link_1_yaw"
    type="revolute">
    <origin
      xyz="-0.00050155183276912 0.686793643713439 0.0155010481432086"
      rpy="0 -0.0763876794035917 3.14159265358979" />
    <parent
      link="starlink_space_manipulator_Mid_arm_Link_1" />
    <child
      link="starlink_space_manipulator_Upper_wrist_Link_1" />
    <axis
      xyz="0 -1 0" />
    <limit
      lower="-3.14"
      upper="3.14"
      effort="0"
      velocity="0" />
  </joint>
  <link
    name="starlink_space_manipulator_Upper_wrist_Link_2">
    <inertial>
      <origin
        xyz="8.45304168883843E-08 0.0848318719623631 -0.00515657391755576"
        rpy="0 0 0" />
      <mass
        value="1.03716823037577" />
      <inertia
        ixx="0.0100970561498589"
        ixy="1.32295633551837E-09"
        ixz="-9.43675929999229E-09"
        iyy="0.00222325407426665"
        iyz="-2.08772874866187E-06"
        izz="0.0105840577017538" />
    </inertial>
    <visual>
      <origin
        xyz="0 0 0"
        rpy="0 0 0" />
      <geometry>
        <mesh
          filename="package://starlink_space_manipulator_merged.SLDASM9/meshes/starlink_space_manipulator_Upper_wrist_Link_2.STL" />
      </geometry>
      <material
        name="">
        <color
          rgba="1 1 1 1" />
      </material>
    </visual>
    <collision>
      <origin
        xyz="0 0 0"
        rpy="0 0 0" />
      <geometry>
        <mesh
          filename="package://starlink_space_manipulator_merged.SLDASM9/meshes/starlink_space_manipulator_Upper_wrist_Link_2.STL" />
      </geometry>
    </collision>
  </link>
  <joint
    name="starlink_space_manipulator_Upper_wrist_Link_2_roll"
    type="continuous">
    <origin
      xyz="0 -0.30020635628656 0"
      rpy="-0.0158640776811277 -0.0317448426184613 -2.67805461574742" />
    <parent
      link="starlink_space_manipulator_Upper_wrist_Link_1" />
    <child
      link="starlink_space_manipulator_Upper_wrist_Link_2" />
    <axis
      xyz="0 0 1" />
    <limit
      lower="-2.5"
      upper="1.8"
      effort="0"
      velocity="0" />
  </joint>
  <link
    name="starlink__space_manipulator_2F-Body_Link">
    <inertial>
      <origin
        xyz="0.000132893636818288 -0.122912145301831 0.000141178527731878"
        rpy="0 0 0" />
      <mass
        value="2.06098061435798" />
      <inertia
        ixx="0.00357820981002093"
        ixy="-9.7173781739015E-06"
        ixz="-0.000377950837415894"
        iyy="0.00540179107539635"
        iyz="3.57093943209629E-06"
        izz="0.0050632324449311" />
    </inertial>
    <visual>
      <origin
        xyz="0 0 0"
        rpy="0 0 0" />
      <geometry>
        <mesh
          filename="package://starlink_space_manipulator_merged.SLDASM9/meshes/starlink__space_manipulator_2F-Body_Link.STL" />
      </geometry>
      <material
        name="">
        <color
          rgba="0.792156862745098 0.819607843137255 0.933333333333333 1" />
      </material>
    </visual>
    <collision>
      <origin
        xyz="0 0 0"
        rpy="0 0 0" />
      <geometry>
        <mesh
          filename="package://starlink_space_manipulator_merged.SLDASM9/meshes/starlink__space_manipulator_2F-Body_Link.STL" />
      </geometry>
    </collision>
  </link>
  <joint
    name="starlink__space_manipulator_2F-Body_Link_yaw"
    type="revolute">
    <origin
      xyz="0 0.34845 -0.0053813"
      rpy="-3.1416 0.93592 0" />
    <parent
      link="starlink_space_manipulator_Upper_wrist_Link_2" />
    <child
      link="starlink__space_manipulator_2F-Body_Link" />
    <axis
      xyz="0 -1 0" />
    <limit
      lower="-3.14"
      upper="3.14"
      effort="0"
      velocity="0" />
  </joint>
  <link
    name="starlink_space_manipulator_Finger1_2_Link">
    <inertial>
      <origin
        xyz="-0.128379781160824 0.00213384929263816 0.20765530277947"
        rpy="0 0 0" />
      <mass
        value="0.164012557851557" />
      <inertia
        ixx="0.000137377814382494"
        ixy="5.75324125943043E-07"
        ixz="1.56204374379134E-05"
        iyy="0.000128174497717794"
        iyz="2.8915711708103E-06"
        izz="5.56877077151319E-05" />
    </inertial>
    <visual>
      <origin
        xyz="0 0 0"
        rpy="0 0 0" />
      <geometry>
        <mesh
          filename="package://starlink_space_manipulator_merged.SLDASM9/meshes/starlink_space_manipulator_Finger1_2_Link.STL" />
      </geometry>
      <material
        name="">
        <color
          rgba="1 1 1 1" />
      </material>
    </visual>
    <collision>
      <origin
        xyz="0 0 0"
        rpy="0 0 0" />
      <geometry>
        <mesh
          filename="package://starlink_space_manipulator_merged.SLDASM9/meshes/starlink_space_manipulator_Finger1_2_Link.STL" />
      </geometry>
    </collision>
  </link>
  <joint
    name="starlink_space_manipulator_Finger1_2_Link_roll"
    type="prismatic">
    <origin
      xyz="-0.2017 -0.10916 -0.04801"
      rpy="-1.5708 0.22747 -3.1416" />
    <parent
      link="starlink__space_manipulator_2F-Body_Link" />
    <child
      link="starlink_space_manipulator_Finger1_2_Link" />
    <axis
      xyz="-1 0 0" />
    <limit
      lower="-0.01"
      upper="0.06"
      effort="0"
      velocity="0" />
  </joint>
  <link
    name="starlink_space_manipulator_Finger2_1_Link">
    <inertial>
      <origin
        xyz="-0.128379783275286 0.0021338497374519 0.207655316264438"
        rpy="0 0 0" />
      <mass
        value="0.164012525176243" />
      <inertia
        ixx="0.000137377758573247"
        ixy="5.75327227385201E-07"
        ixz="1.56204303396715E-05"
        iyy="0.00012817444752134"
        iyz="2.89153901545968E-06"
        izz="5.5687711839857E-05" />
    </inertial>
    <visual>
      <origin
        xyz="0 0 0"
        rpy="0 0 0" />
      <geometry>
        <mesh
          filename="package://starlink_space_manipulator_merged.SLDASM9/meshes/starlink_space_manipulator_Finger2_1_Link.STL" />
      </geometry>
      <material
        name="">
        <color
          rgba="1 1 1 1" />
      </material>
    </visual>
    <collision>
      <origin
        xyz="0 0 0"
        rpy="0 0 0" />
      <geometry>
        <mesh
          filename="package://starlink_space_manipulator_merged.SLDASM9/meshes/starlink_space_manipulator_Finger2_1_Link.STL" />
      </geometry>
    </collision>
  </link>
  <joint
    name="starlink_space_manipulator_Finger2_1_Link_roll"
    type="prismatic">
    <origin
      xyz="0.20865 -0.10916 0.049619"
      rpy="1.5708 -0.22747 0" />
    <parent
      link="starlink__space_manipulator_2F-Body_Link" />
    <child
      link="starlink_space_manipulator_Finger2_1_Link" />
    <axis
      xyz="-1 0 0" />
    <limit
      lower="-0.01"
      upper="0.06"
      effort="0"
      velocity="0" />
  </joint>
</robot>