<?xml version="1.0" encoding="utf-8"?>
<!-- This URDF was automatically created by SolidWorks to URDF Exporter! Originally created by Stephen Brawner (brawner@gmail.com) 
     Commit Version: 1.6.0-4-g7f85cfe  Build Version: 1.6.7995.38578
     For more information, please see http://wiki.ros.org/sw_urdf_exporter -->
<robot
  name="卫星1号urdf.SLDASM">
  <link
    name="base_link">
    <inertial>
      <origin
        xyz="-0.0021734 0.01739 1.8681"
        rpy="0 0 0" />
      <mass
        value="12177" />
      <inertia
        ixx="24010"
        ixy="22.551"
        ixz="-5.9494"
        iyy="22718"
        iyz="-26.782"
        izz="7737.8" />
    </inertial>
    <visual>
      <origin
        xyz="0 0 0"
        rpy="0 0 0" />
      <geometry>
        <mesh
          filename="package://卫星1号urdf.SLDASM/meshes/base_link.STL" />
      </geometry>
      <material
        name="">
        <color
          rgba="0.79216 0.81961 0.93333 0.25" />
      </material>
    </visual>
    <collision>
      <origin
        xyz="0 0 0"
        rpy="0 0 0" />
      <geometry>
        <mesh
          filename="package://卫星1号urdf.SLDASM/meshes/base_link.STL" />
      </geometry>
    </collision>
  </link>
  <link
    name="taiyangban_Link">
    <inertial>
      <origin
        xyz="-2.81413785386819E-05 -0.00098378177057673 4.93893038676484"
        rpy="0 0 0" />
      <mass
        value="738.165777813078" />
      <inertia
        ixx="5127.11940243927"
        ixy="-5.2573675695612"
        ixz="0.0045557067928942"
        iyy="4943.47984737629"
        iyz="0.159260900777422"
        izz="184.248094037069" />
    </inertial>
    <visual>
      <origin
        xyz="0 0 0"
        rpy="0 0 0" />
      <geometry>
        <mesh
          filename="package://卫星1号urdf.SLDASM/meshes/taiyangban_Link.STL" />
      </geometry>
      <material
        name="">
        <color
          rgba="1 1 1 1" />
      </material>
    </visual>
    <collision>
      <origin
        xyz="0 0 0"
        rpy="0 0 0" />
      <geometry>
        <mesh
          filename="package://卫星1号urdf.SLDASM/meshes/taiyangban_Link.STL" />
      </geometry>
    </collision>
  </link>
  <joint
    name="tyb1"
    type="continuous">
    <origin
      xyz="0.92 -0.3 0.775"
      rpy="0 1.5708 0" />
    <parent
      link="base_link" />
    <child
      link="taiyangban_Link" />
    <axis
      xyz="0 0 -1" />
  </joint>
  <link
    name="taiyangban2_Link">
    <inertial>
      <origin
        xyz="0 0 0"
        rpy="0 0 0" />
      <mass
        value="0" />
      <inertia
        ixx="0"
        ixy="0"
        ixz="0"
        iyy="0"
        iyz="0"
        izz="0" />
    </inertial>
    <visual>
      <origin
        xyz="0 0 0"
        rpy="0 0 0" />
      <geometry>
        <mesh
          filename="package://卫星1号urdf.SLDASM/meshes/taiyangban2_Link.STL" />
      </geometry>
      <material
        name="">
        <color
          rgba="1 1 1 1" />
      </material>
    </visual>
    <collision>
      <origin
        xyz="0 0 0"
        rpy="0 0 0" />
      <geometry>
        <mesh
          filename="package://卫星1号urdf.SLDASM/meshes/taiyangban2_Link.STL" />
      </geometry>
    </collision>
  </link>
  <joint
    name="tyb2"
    type="continuous">
    <origin
      xyz="-0.9 -0.3 0.775"
      rpy="3.1416 1.5708 0" />
    <parent
      link="base_link" />
    <child
      link="taiyangban2_Link" />
    <axis
      xyz="0 0 1" />
  </joint>
</robot>