<?xml version="1.0" ?>
<robot name="satellite_combine_panda">
  <link name="satellite_base_link">
    <inertial>
      <origin xyz="0.10106 -0.035329 0.077989" rpy="0 0 0"/>
      <mass value="2033.4"/>
      <inertia ixx="1247.2" ixy="-46.734" ixz="25.188" iyy="1152.9" iyz="-10.391" izz="913.45"/>
    </inertial>
    <visual>
      <origin xyz="0 0 0" rpy="0 0 0"/>
      <geometry>
        <mesh filename="./meshes/base_link.STL"/>
      </geometry>
      <material name="">
        <color rgba="0.79216 0.81961 0.93333 1"/>
        <texture filename="./textures/3.png"/>
      </material>
    </visual>
    <collision>
      <origin xyz="0 0 0" rpy="0 0 0"/>
      <geometry>
        <mesh filename="./meshes/base_link.STL"/>
      </geometry>
    </collision>
  </link>
  <link name="satellite_right_Link">
    <inertial>
      <origin xyz="4.8572E-16 -2.9005E-15 -0.07437" rpy="0 0 0"/>
      <mass value="812.47"/>
      <inertia ixx="3662.9" ixy="-6.7748E-07" ixz="-9.5225E-13" iyy="3143.1" iyz="1.2981E-12" izz="520.78"/>
    </inertial>
    <visual>
      <origin xyz="0 0 0" rpy="0 0 0"/>
      <geometry>
        <mesh filename="./meshes/right_Link.STL"/>
      </geometry>
      <material name="">
        <color rgba="0.79216 0.81961 0.93333 1"/>
        <texture filename="./textures/5.png"/>
      </material>
    </visual>
    <collision>
      <origin xyz="0 0 0" rpy="0 0 0"/>
      <geometry>
        <mesh filename="./meshes/right_Link.STL"/>
      </geometry>
    </collision>
  </link>
  <joint name="satellite_right_joint" type="fixed">
    <origin xyz="0.0075184 -4.5591 0.0015235" rpy="1.5708 -0.8237 0"/>
    <parent link="satellite_base_link"/>
    <child link="satellite_right_Link"/>
    <axis xyz="0 0 0"/>
  </joint>
  <link name="satellite_left_Link">
    <inertial>
      <origin xyz="0 0 0" rpy="0 0 0"/>
      <mass value="812.47"/>
      <inertia ixx="3662.9" ixy="-6.7748E-07" ixz="-9.5225E-13" iyy="3143.1" iyz="1.2981E-12" izz="520.78"/>
    </inertial>
    <visual>
      <origin xyz="0 0 0" rpy="0 0 0"/>
      <geometry>
        <mesh filename="./meshes/left_Link.STL"/>
      </geometry>
      <material name="">
        <color rgba="1 1 1 1"/>
        <texture filename="./textures/5.png"/>
      </material>
    </visual>
    <collision>
      <origin xyz="0 0 0" rpy="0 0 0"/>
      <geometry>
        <mesh filename="./meshes/left_Link.STL"/>
      </geometry>
    </collision>
  </link>
  <joint name="satellite_left_joint" type="fixed">
    <origin xyz="0.0044704 4.5591 -0.0015245" rpy="-1.5708 -0.8237 0"/>
    <parent link="satellite_base_link"/>
    <child link="satellite_left_Link"/>
    <axis xyz="0 0 0"/>
  </joint>
  <link name="satellite_attachment">
    <inertial>
      <origin rpy="0 0 0" xyz="0 0 0"/>
      <mass value="0.01"/>
      <inertia ixx="0.1" ixy="0" ixz="0" iyy="0.1" iyz="0" izz="0.1"/>
    </inertial>
  </link>
  <joint name="satellite_fix_joint" type="fixed">
    <origin rpy="0 -1.57 0" xyz="-0.9144 0.0 1.4"/>
    <parent link="satellite_base_link"/>
    <child link="satellite_attachment"/>
    <axis xyz="0 0 0"/>
  </joint>
  <link name="panda_link0">
    <inertial>
      <origin rpy="0 0 0" xyz="0.0 0.0 0.15000000000000002"/>
      <mass value="78.3"/>
      <inertia ixx="24.3" ixy="0" ixz="0" iyy="24.3" iyz="0" izz="24.3"/>
    </inertial>
    <visual>
      <geometry>
        <mesh filename="./meshes/collision/link0.obj" scale="3.0 3.0 3.0"/>
      </geometry>
      <material name="panda_white">
        <color rgba="1. 1. 1. 1."/>
      </material>
    </visual>
    <collision>
      <geometry>
        <mesh filename="./meshes/collision/link0.obj" scale="3.0 3.0 3.0"/>
      </geometry>
      <material name="panda_white"/>
    </collision>
  </link>
  <link name="panda_link1">
    <inertial>
      <origin rpy="0 0 0" xyz="0.0 -0.12 -0.15000000000000002"/>
      <mass value="72.9"/>
      <inertia ixx="24.3" ixy="0" ixz="0" iyy="24.3" iyz="0" izz="24.3"/>
    </inertial>
    <visual>
      <geometry>
        <mesh filename="./meshes/visual/link1.obj" scale="3.0 3.0 3.0"/>
      </geometry>
      <material name="panda_white"/>
    </visual>
    <collision>
      <geometry>
        <mesh filename="./meshes/collision/link1.obj" scale="3.0 3.0 3.0"/>
      </geometry>
      <material name="panda_white"/>
    </collision>
  </link>
  <joint name="panda_joint1" type="revolute">
    <safety_controller k_position="100.0" k_velocity="40.0" soft_lower_limit="-2.8973" soft_upper_limit="2.8973"/>
    <origin rpy="0 0 0" xyz="0.0 0.0 0.9990000000000001"/>
    <parent link="panda_link0"/>
    <child link="panda_link1"/>
    <axis xyz="0 0 1"/>
    <limit effort="87" lower="-2.9671" upper="2.9671" velocity="2.1750"/>
  </joint>
  <link name="panda_link2">
    <inertial>
      <origin rpy="0 0 0" xyz="0.0 -0.12 0.18"/>
      <mass value="73.71"/>
      <inertia ixx="24.3" ixy="0" ixz="0" iyy="24.3" iyz="0" izz="24.3"/>
    </inertial>
    <visual>
      <geometry>
        <mesh filename="./meshes/visual/link2.obj" scale="3.0 3.0 3.0"/>
      </geometry>
      <material name="panda_white"/>
    </visual>
    <collision>
      <geometry>
        <mesh filename="./meshes/collision/link2.obj" scale="3.0 3.0 3.0"/>
      </geometry>
      <material name="panda_white"/>
    </collision>
  </link>
  <joint name="panda_joint2" type="revolute">
    <safety_controller k_position="100.0" k_velocity="40.0" soft_lower_limit="-1.7628" soft_upper_limit="1.7628"/>
    <origin rpy="-1.57079632679 0 0" xyz="0.0 0.0 0.0"/>
    <parent link="panda_link1"/>
    <child link="panda_link2"/>
    <axis xyz="0 0 1"/>
    <limit effort="87" lower="-1.8326" upper="1.8326" velocity="2.1750"/>
  </joint>
  <link name="panda_link3">
    <inertial>
      <origin rpy="0 0 0" xyz="0.03 0.03 -0.15000000000000002"/>
      <mass value="55.08"/>
      <inertia ixx="24.3" ixy="0" ixz="0" iyy="24.3" iyz="0" izz="24.3"/>
    </inertial>
    <visual>
      <geometry>
        <mesh filename="./meshes/visual/link3.obj" scale="3.0 3.0 3.0"/>
      </geometry>
      <material name="panda_red">
        <color rgba="1. 1. 1. 1."/>
      </material>
    </visual>
    <collision>
      <geometry>
        <mesh filename="./meshes/collision/link3.obj" scale="3.0 3.0 3.0"/>
      </geometry>
    </collision>
  </link>
  <joint name="panda_joint3" type="revolute">
    <safety_controller k_position="100.0" k_velocity="40.0" soft_lower_limit="-2.8973" soft_upper_limit="2.8973"/>
    <origin rpy="1.57079632679 0 0" xyz="0.0 -0.948 0.0"/>
    <parent link="panda_link2"/>
    <child link="panda_link3"/>
    <axis xyz="0 0 1"/>
    <limit effort="87" lower="-2.9671" upper="2.9671" velocity="2.1750"/>
  </joint>
  <link name="panda_link4">
    <inertial>
      <origin rpy="0 0 0" xyz="-0.09 0.09 0.06"/>
      <mass value="56.160000000000004"/>
      <inertia ixx="24.3" ixy="0" ixz="0" iyy="24.3" iyz="0" izz="24.3"/>
    </inertial>
    <visual>
      <geometry>
        <mesh filename="./meshes/visual/link4.obj" scale="3.0 3.0 3.0"/>
      </geometry>
      <material name="panda_white"/>
    </visual>
    <collision>
      <geometry>
        <mesh filename="./meshes/collision/link4.obj" scale="3.0 3.0 3.0"/>
      </geometry>
      <material name="panda_white"/>
    </collision>
  </link>
  <joint name="panda_joint4" type="revolute">
    <safety_controller k_position="100.0" k_velocity="40.0" soft_lower_limit="-3.0718" soft_upper_limit="-0.0698"/>
    <origin rpy="1.57079632679 0 0" xyz="0.2475 0.0 0.0"/>
    <parent link="panda_link3"/>
    <child link="panda_link4"/>
    <axis xyz="0 0 1"/>
    <limit effort="87" lower="-3.1416" upper="0.0" velocity="2.1750"/>
  </joint>
  <link name="panda_link5">
    <inertial>
      <origin rpy="0 0 0" xyz="0.0 0.12 -0.36"/>
      <mass value="81.0"/>
      <inertia ixx="24.3" ixy="0" ixz="0" iyy="24.3" iyz="0" izz="24.3"/>
    </inertial>
    <visual>
      <geometry>
        <mesh filename="./meshes/visual/link5.obj" scale="3.0 3.0 3.0"/>
      </geometry>
      <material name="panda_white"/>
    </visual>
    <collision>
      <geometry>
        <mesh filename="./meshes/collision/link5.obj" scale="3.0 3.0 3.0"/>
      </geometry>
      <material name="panda_white"/>
    </collision>
  </link>
  <joint name="panda_joint5" type="revolute">
    <safety_controller k_position="100.0" k_velocity="40.0" soft_lower_limit="-2.8973" soft_upper_limit="2.8973"/>
    <origin rpy="-1.57079632679 0 0" xyz="-0.2475 1.1520000000000001 0.0"/>
    <parent link="panda_link4"/>
    <child link="panda_link5"/>
    <axis xyz="0 0 1"/>
    <limit effort="12" lower="-2.9671" upper="2.9671" velocity="2.6100"/>
  </joint>
  <link name="panda_link6">
    <inertial>
      <origin rpy="0 0 0" xyz="0.12 0.0 0.0"/>
      <mass value="35.1"/>
      <inertia ixx="24.3" ixy="0" ixz="0" iyy="24.3" iyz="0" izz="24.3"/>
    </inertial>
    <visual>
      <geometry>
        <mesh filename="./meshes/visual/link6.obj" scale="3.0 3.0 3.0"/>
      </geometry>
      <material name="panda_white"/>
    </visual>
    <collision>
      <geometry>
        <mesh filename="./meshes/collision/link6.obj" scale="3.0 3.0 3.0"/>
      </geometry>
      <material name="panda_white"/>
    </collision>
  </link>
  <joint name="panda_joint6" type="revolute">
    <safety_controller k_position="100.0" k_velocity="40.0" soft_lower_limit="-0.0175" soft_upper_limit="3.7525"/>
    <origin rpy="1.57079632679 0 0" xyz="0.0 0.0 0.0"/>
    <parent link="panda_link5"/>
    <child link="panda_link6"/>
    <axis xyz="0 0 1"/>
    <limit effort="12" lower="-0.0873" upper="3.8223" velocity="2.6100"/>
  </joint>
  <link name="panda_link7">
    <inertial>
      <origin rpy="0 0 0" xyz="0.0 0.0 0.24"/>
      <mass value="5.4"/>
      <inertia ixx="24.3" ixy="0" ixz="0" iyy="24.3" iyz="0" izz="24.3"/>
    </inertial>
    <visual>
      <geometry>
        <mesh filename="./meshes/collision/link7.obj" scale="3.0 3.0 3.0"/>
      </geometry>
      <material name="panda_white"/>
    </visual>
    <collision>
      <geometry>
        <mesh filename="./meshes/collision/link7.obj" scale="3.0 3.0 3.0"/>
      </geometry>
      <material name="panda_white"/>
    </collision>
  </link>
  <joint name="panda_joint7" type="revolute">
    <safety_controller k_position="100.0" k_velocity="40.0" soft_lower_limit="-2.8973" soft_upper_limit="2.8973"/>
    <origin rpy="1.57079632679 0 0" xyz="0.264 0.0 0.0"/>
    <parent link="panda_link6"/>
    <child link="panda_link7"/>
    <axis xyz="0 0 1"/>
    <limit effort="12" lower="-2.9671" upper="2.9671" velocity="2.6100"/>
  </joint>
  <link name="panda_link8">
    <inertial>
      <origin rpy="0 0 0" xyz="0.0 0.0 0.0"/>
      <mass value="0.0"/>
      <inertia ixx="24.3" ixy="0" ixz="0" iyy="24.3" iyz="0" izz="24.3"/>
    </inertial>
  </link>
  <joint name="panda_joint8" type="fixed">
    <origin rpy="0 0 0" xyz="0.0 0.0 0.321"/>
    <parent link="panda_link7"/>
    <child link="panda_link8"/>
    <axis xyz="0 0 0"/>
  </joint>
  <joint name="panda_hand_joint" type="fixed">
    <parent link="panda_link8"/>
    <child link="panda_hand"/>
    <origin rpy="0 0 -0.785398163397" xyz="0.0 0.0 0.0"/>
  </joint>
  <link name="panda_hand">
    <inertial>
      <origin rpy="0 0 0" xyz="0.0 0.0 0.12"/>
      <mass value="21.87"/>
      <inertia ixx="24.3" ixy="0" ixz="0" iyy="24.3" iyz="0" izz="24.3"/>
    </inertial>
    <visual>
      <geometry>
        <mesh filename="./meshes/visual/hand.obj" scale="3.0 3.0 3.0"/>
      </geometry>
      <material name="panda_white"/>
    </visual>
    <collision>
      <geometry>
        <mesh filename="./meshes/collision/hand.obj" scale="3.0 3.0 3.0"/>
      </geometry>
      <material name="panda_white"/>
    </collision>
  </link>
  <link name="panda_leftfinger">
    <contact>
      <friction_anchor/>
      <stiffness value="30000.0"/>
      <damping value="1000.0"/>
      <spinning_friction value="0.1"/>
      <lateral_friction value="1.0"/>
    </contact>
    <inertial>
      <origin rpy="0 0 0" xyz="0.0 0.03 0.06"/>
      <mass value="2.7"/>
      <inertia ixx="24.3" ixy="0" ixz="0" iyy="24.3" iyz="0" izz="24.3"/>
    </inertial>
    <visual>
      <geometry>
        <mesh filename="./meshes/visual/finger.obj" scale="3.0 3.0 3.0"/>
      </geometry>
      <material name="panda_white"/>
    </visual>
    <collision>
      <geometry>
        <mesh filename="./meshes/collision/finger.obj" scale="3.0 3.0 3.0"/>
      </geometry>
      <material name="panda_white"/>
    </collision>
  </link>
  <link name="panda_rightfinger">
    <contact>
      <friction_anchor/>
      <stiffness value="30000.0"/>
      <damping value="1000.0"/>
      <spinning_friction value="0.1"/>
      <lateral_friction value="1.0"/>
    </contact>
    <inertial>
      <origin rpy="0 0 0" xyz="0.0 -0.03 0.06"/>
      <mass value="2.7"/>
      <inertia ixx="24.3" ixy="0" ixz="0" iyy="24.3" iyz="0" izz="24.3"/>
    </inertial>
    <visual>
      <origin rpy="0 0 3.14159265359" xyz="0 0 0"/>
      <geometry>
        <mesh filename="./meshes/visual/finger.obj" scale="3.0 3.0 3.0"/>
      </geometry>
      <material name="panda_white"/>
    </visual>
    <collision>
      <origin rpy="0 0 3.14159265359" xyz="0 0 0"/>
      <geometry>
        <mesh filename="./meshes/collision/finger.obj" scale="3.0 3.0 3.0"/>
      </geometry>
      <material name="panda_white"/>
    </collision>
  </link>
  <joint name="panda_finger_joint1" type="prismatic">
    <parent link="panda_hand"/>
    <child link="panda_leftfinger"/>
    <origin rpy="0 0 0" xyz="0.0 0.0 0.1752"/>
    <axis xyz="0 1 0"/>
    <limit effort="20" lower="0.0" upper="0.04" velocity="0.2"/>
  </joint>
  <joint name="panda_finger_joint2" type="prismatic">
    <parent link="panda_hand"/>
    <child link="panda_rightfinger"/>
    <origin rpy="0 0 0" xyz="0.0 0.0 0.1752"/>
    <axis xyz="0 -1 0"/>
    <limit effort="20" lower="0.0" upper="0.04" velocity="0.2"/>
    <mimic joint="panda_finger_joint1"/>
  </joint>
  <link name="panda_grasptarget">
    <inertial>
      <origin rpy="0 0 0" xyz="0.0 0.0 0.0"/>
      <mass value="0.0"/>
      <inertia ixx="24.3" ixy="0" ixz="0" iyy="24.3" iyz="0" izz="24.3"/>
    </inertial>
  </link>
  <joint name="panda_grasptarget_hand" type="fixed">
    <parent link="panda_hand"/>
    <child link="panda_grasptarget"/>
    <origin rpy="0 0 0" xyz="0.0 0.0 0.315"/>
  </joint>
  <joint name="satellite_panda_connection_joint" type="fixed">
    <parent link="satellite_attachment"/>
    <child link="panda_link0"/>
    <origin xyz="-1 0 0" rpy="0 0 0"/>
  </joint>
</robot>