<?xml version="1.0" encoding="utf-8"?>
<!-- This URDF was automatically created by SolidWorks to URDF Exporter! Originally created by Stephen Brawner (brawner@gmail.com) 
     Commit Version: 1.6.0-1-g15f4949  Build Version: 1.6.7594.29634
     For more information, please see http://wiki.ros.org/sw_urdf_exporter -->
<robot
  name="机械臂">
  <link
    name="base_link">
    <inertial>
      <origin
        xyz="0.175000065234684 -1.28353998601978 0.0846256448065584"
        rpy="0 0 0" />
      <mass
        value="9.63410834932178" />
      <inertia
        ixx="0.118228807956081"
        ixy="-5.0957321181862E-07"
        ixz="1.72062364122864E-09"
        iyy="0.118225953121689"
        iyz="4.16913652507129E-17"
        izz="0.137194156018786" />
    </inertial>
    <visual>
      <origin
        xyz="0 0 0"
        rpy="0 0 0" />
      <geometry>
        <mesh
          filename="package://机械臂/meshes/base_link.STL" />
      </geometry>
      <material
        name="">
        <color
          rgba="1 1 1 1" />
      </material>
    </visual>
    <collision>
      <origin
        xyz="0 0 0"
        rpy="0 0 0" />
      <geometry>
        <mesh
          filename="package://机械臂/meshes/base_link.STL" />
      </geometry>
    </collision>
  </link>
  <link
    name="Link1">
    <inertial>
      <origin
        xyz="-0.10023640362579 -0.00344641251692088 0.174250351355485"
        rpy="0 0 0" />
      <mass
        value="5.17491872844292" />
      <inertia
        ixx="0.0304221927243367"
        ixy="0.00255793298706213"
        ixz="0.000566537933529525"
        iyy="0.0524628663009184"
        iyz="-5.38795635070424E-05"
        izz="0.0437592826397428" />
    </inertial>
    <visual>
      <origin
        xyz="0 0 0"
        rpy="0 0 0" />
      <geometry>
        <mesh
          filename="package://机械臂/meshes/Link1.STL" />
      </geometry>
      <material
        name="">
        <color
          rgba="1 1 1 1" />
      </material>
    </visual>
    <collision>
      <origin
        xyz="0 0 0"
        rpy="0 0 0" />
      <geometry>
        <mesh
          filename="package://机械臂/meshes/Link1.STL" />
      </geometry>
    </collision>
  </link>
  <joint
    name="joint1"
    type="revolute">
    <origin
      xyz="0.175 -1.28353998602675 0.180000000000021"
      rpy="0 0 -1.5707963267949" />
    <parent
      link="base_link" />
    <child
      link="Link1" />
    <axis
      xyz="0 0 -1" />
    <limit
      lower="0"
      upper="0"
      effort="0"
      velocity="0" />
  </joint>
  <link
    name="Link2">
    <inertial>
      <origin
        xyz="0.466771973200787 -0.0200679208590893 0.656279146890149"
        rpy="0 0 0" />
      <mass
        value="5.06670898247749" />
      <inertia
        ixx="0.3470792896805"
        ixy="1.04550875056428E-05"
        ixz="-0.229276580302284"
        iyy="0.500779642027053"
        iyz="1.48421856668549E-05"
        izz="0.187791160297581" />
    </inertial>
    <visual>
      <origin
        xyz="0 0 0"
        rpy="0 0 0" />
      <geometry>
        <mesh
          filename="package://机械臂/meshes/Link2.STL" />
      </geometry>
      <material
        name="">
        <color
          rgba="1 1 1 1" />
      </material>
    </visual>
    <collision>
      <origin
        xyz="0 0 0"
        rpy="0 0 0" />
      <geometry>
        <mesh
          filename="package://机械臂/meshes/Link2.STL" />
      </geometry>
    </collision>
  </link>
  <joint
    name="joint2"
    type="revolute">
    <origin
      xyz="-0.199999999999705 -0.164019999999946 0.179999999999324"
      rpy="0 0 0" />
    <parent
      link="Link1" />
    <child
      link="Link2" />
    <axis
      xyz="0 -1 0" />
    <limit
      lower="0"
      upper="0"
      effort="0"
      velocity="0" />
  </joint>
  <link
    name="Link3">
    <inertial>
      <origin
        xyz="-0.26645118399556 -0.079424732084338 0.38167788397144"
        rpy="0 0 0" />
      <mass
        value="3.09946963131409" />
      <inertia
        ixx="0.149105958907437"
        ixy="-1.89957749734383E-05"
        ixz="0.0977586144353564"
        iyy="0.219315567296226"
        iyz="2.72491726693336E-05"
        izz="0.0773167516090272" />
    </inertial>
    <visual>
      <origin
        xyz="0 0 0"
        rpy="0 0 0" />
      <geometry>
        <mesh
          filename="package://机械臂/meshes/Link3.STL" />
      </geometry>
      <material
        name="">
        <color
          rgba="1 1 1 1" />
      </material>
    </visual>
    <collision>
      <origin
        xyz="0 0 0"
        rpy="0 0 0" />
      <geometry>
        <mesh
          filename="package://机械臂/meshes/Link3.STL" />
      </geometry>
    </collision>
  </link>
  <joint
    name="joint3"
    type="revolute">
    <origin
      xyz="0.695520649063987 0.219020000000473 0.97788088575548"
      rpy="0 0 0" />
    <parent
      link="Link2" />
    <child
      link="Link3" />
    <axis
      xyz="0 1 0" />
    <limit
      lower="0"
      upper="0"
      effort="0"
      velocity="0" />
  </joint>
  <link
    name="Link4">
    <inertial>
      <origin
        xyz="0.0339777660443481 -0.108927859924944 -5.01533037322588E-09"
        rpy="0 0 0" />
      <mass
        value="1.32312071913896" />
      <inertia
        ixx="0.0040376799409881"
        ixy="2.8629913833031E-06"
        ixz="-4.78825536786573E-11"
        iyy="0.0025574469782764"
        iyz="-2.53060943732125E-10"
        izz="0.00390753680935879" />
    </inertial>
    <visual>
      <origin
        xyz="0 0 0"
        rpy="0 0 0" />
      <geometry>
        <mesh
          filename="package://机械臂/meshes/Link4.STL" />
      </geometry>
      <material
        name="">
        <color
          rgba="1 1 1 1" />
      </material>
    </visual>
    <collision>
      <origin
        xyz="0 0 0"
        rpy="0 0 0" />
      <geometry>
        <mesh
          filename="package://机械臂/meshes/Link4.STL" />
      </geometry>
    </collision>
  </link>
  <joint
    name="joint4"
    type="revolute">
    <origin
      xyz="-0.466520649051403 -0.211099999835117 0.668269020696948"
      rpy="0 0 0" />
    <parent
      link="Link3" />
    <child
      link="Link4" />
    <axis
      xyz="0 1 0" />
    <limit
      lower="0"
      upper="0"
      effort="0"
      velocity="0" />
  </joint>
  <link
    name="Link5">
    <inertial>
      <origin
        xyz="0.116820494902411 -0.0388858014695093 9.49856462728604E-05"
        rpy="0 0 0" />
      <mass
        value="1.49665109696271" />
      <inertia
        ixx="0.00362010787485334"
        ixy="2.87189467699518E-06"
        ixz="-7.52821732655946E-09"
        iyy="0.00411237521489435"
        iyz="2.18423673209098E-06"
        izz="0.00497019007843053" />
    </inertial>
    <visual>
      <origin
        xyz="0 0 0"
        rpy="0 0 0" />
      <geometry>
        <mesh
          filename="package://机械臂/meshes/Link5.STL" />
      </geometry>
      <material
        name="">
        <color
          rgba="1 1 1 1" />
      </material>
    </visual>
    <collision>
      <origin
        xyz="0 0 0"
        rpy="0 0 0" />
      <geometry>
        <mesh
          filename="package://机械臂/meshes/Link5.STL" />
      </geometry>
    </collision>
  </link>
  <joint
    name="joint5"
    type="revolute">
    <origin
      xyz="0.157999999987109 -0.17700000017881 0"
      rpy="0 0 0" />
    <parent
      link="Link4" />
    <child
      link="Link5" />
    <axis
      xyz="-1 0 0" />
    <limit
      lower="0"
      upper="0"
      effort="0"
      velocity="0" />
  </joint>
  <link
    name="Link6">
    <inertial>
      <origin
        xyz="2.28098209260619E-05 -0.0320807203623127 -5.37221285679124E-07"
        rpy="0 0 0" />
      <mass
        value="0.225883780891649" />
      <inertia
        ixx="0.000200276096336215"
        ixy="1.12516805106898E-07"
        ixz="-8.90541740359369E-09"
        iyy="0.000134409410807654"
        iyz="-4.88400860706578E-10"
        izz="0.000175807968226694" />
    </inertial>
    <visual>
      <origin
        xyz="0 0 0"
        rpy="0 0 0" />
      <geometry>
        <mesh
          filename="package://机械臂/meshes/Link6.STL" />
      </geometry>
      <material
        name="">
        <color
          rgba="1 1 1 1" />
      </material>
    </visual>
    <collision>
      <origin
        xyz="0 0 0"
        rpy="0 0 0" />
      <geometry>
        <mesh
          filename="package://机械臂/meshes/Link6.STL" />
      </geometry>
    </collision>
  </link>
  <joint
    name="joint6"
    type="revolute">
    <origin
      xyz="0.176999999990653 -0.167999494802491 0.000411998519138201"
      rpy="-0.00245237457649197 0 0" />
    <parent
      link="Link5" />
    <child
      link="Link6" />
    <axis
      xyz="0 -1 0" />
    <limit
      lower="0"
      upper="0"
      effort="0"
      velocity="0" />
  </joint>
  <link
    name="Link7">
    <inertial>
      <origin
        xyz="-0.000181478067869945 -0.0317448329689773 0.0398064144277606"
        rpy="0 0 0" />
      <mass
        value="0.0319358386218752" />
      <inertia
        ixx="2.01085931432526E-05"
        ixy="3.12789550275446E-09"
        ixz="-8.8632784447456E-10"
        iyy="5.09514460934359E-06"
        iyz="6.17937194323444E-06"
        izz="1.90791381720628E-05" />
    </inertial>
    <visual>
      <origin
        xyz="0 0 0"
        rpy="0 0 0" />
      <geometry>
        <mesh
          filename="package://机械臂/meshes/Link7.STL" />
      </geometry>
      <material
        name="">
        <color
          rgba="1 1 1 1" />
      </material>
    </visual>
    <collision>
      <origin
        xyz="0 0 0"
        rpy="0 0 0" />
      <geometry>
        <mesh
          filename="package://机械臂/meshes/Link7.STL" />
      </geometry>
    </collision>
  </link>
  <joint
    name="joint7"
    type="revolute">
    <origin
      xyz="0 -0.054663 0.030601"
      rpy="0 0 0" />
    <parent
      link="Link6" />
    <child
      link="Link7" />
    <axis
      xyz="1 0 0" />
    <limit
      lower="0"
      upper="0"
      effort="0"
      velocity="0" />
    <mimic
      joint="joint8"
      multiplier="1"
      offset="0" />
  </joint>
  <link
    name="Link8">
    <inertial>
      <origin
        xyz="-5.00165586529988E-05 -0.0438269624455681 0.0301838581399925"
        rpy="0 0 0" />
      <mass
        value="0.0252265093199784" />
      <inertia
        ixx="1.6808616481803E-05"
        ixy="-2.12045463573026E-11"
        ixz="1.53180584275812E-11"
        iyy="7.9387147036509E-06"
        iyz="7.58011607165621E-06"
        izz="1.36915220963734E-05" />
    </inertial>
    <visual>
      <origin
        xyz="0 0 0"
        rpy="0 0 0" />
      <geometry>
        <mesh
          filename="package://机械臂/meshes/Link8.STL" />
      </geometry>
      <material
        name="">
        <color
          rgba="1 1 1 1" />
      </material>
    </visual>
    <collision>
      <origin
        xyz="0 0 0"
        rpy="0 0 0" />
      <geometry>
        <mesh
          filename="package://机械臂/meshes/Link8.STL" />
      </geometry>
    </collision>
  </link>
  <joint
    name="joint8"
    type="revolute">
    <origin
      xyz="0 -0.061178 0.0127"
      rpy="0 0 0" />
    <parent
      link="Link6" />
    <child
      link="Link8" />
    <axis
      xyz="1 0 0" />
    <limit
      lower="0"
      upper="45"
      effort="0"
      velocity="0" />
  </joint>
  <link
    name="Link11">
    <inertial>
      <origin
        xyz="-0.000200000020441404 0.00181476872250885 0.00846774554587926"
        rpy="0 0 0" />
      <mass
        value="0.00721958961039276" />
      <inertia
        ixx="6.54404874424823E-07"
        ixy="-1.22054472984936E-15"
        ixz="-6.62770202363781E-13"
        iyy="6.47825684492298E-07"
        iyz="-1.54040746931974E-07"
        izz="4.21420299143768E-07" />
    </inertial>
    <visual>
      <origin
        xyz="0 0 0"
        rpy="0 0 0" />
      <geometry>
        <mesh
          filename="package://机械臂/meshes/Link11.STL" />
      </geometry>
      <material
        name="">
        <color
          rgba="1 1 1 1" />
      </material>
    </visual>
    <collision>
      <origin
        xyz="0 0 0"
        rpy="0 0 0" />
      <geometry>
        <mesh
          filename="package://机械臂/meshes/Link11.STL" />
      </geometry>
    </collision>
  </link>
  <joint
    name="joint11"
    type="revolute">
    <origin
      xyz="0 -0.082385 0.05668"
      rpy="0 0 0" />
    <parent
      link="Link8" />
    <child
      link="Link11" />
    <axis
      xyz="1 0 0" />
    <limit
      lower="0"
      upper="0"
      effort="0"
      velocity="0" />
    <mimic
      joint="joint8"
      multiplier="-1"
      offset="0" />
  </joint>
  <link
    name="Link9">
    <inertial>
      <origin
        xyz="-5.00161187924064E-05 -0.0482044913916658 -0.0225431825096782"
        rpy="0 0 0" />
      <mass
        value="0.0252265101127249" />
      <inertia
        ixx="1.6808617666226E-05"
        ixy="-2.37792659310917E-11"
        ixz="-1.04792046679214E-11"
        iyy="5.60564073206646E-06"
        iyz="-6.21234299435615E-06"
        izz="1.60245973553727E-05" />
    </inertial>
    <visual>
      <origin
        xyz="0 0 0"
        rpy="0 0 0" />
      <geometry>
        <mesh
          filename="package://机械臂/meshes/Link9.STL" />
      </geometry>
      <material
        name="">
        <color
          rgba="1 1 1 1" />
      </material>
    </visual>
    <collision>
      <origin
        xyz="0 0 0"
        rpy="0 0 0" />
      <geometry>
        <mesh
          filename="package://机械臂/meshes/Link9.STL" />
      </geometry>
    </collision>
  </link>
  <joint
    name="joint9"
    type="revolute">
    <origin
      xyz="0 -0.061178 -0.0127"
      rpy="0 0 0" />
    <parent
      link="Link6" />
    <child
      link="Link9" />
    <axis
      xyz="-1 0 0" />
    <limit
      lower="0"
      upper="0"
      effort="0"
      velocity="0" />
    <mimic
      joint="joint8"
      multiplier="1"
      offset="0" />
  </joint>
  <link
    name="Link12">
    <inertial>
      <origin
        xyz="1.95898852695109E-11 0.00181476855692436 -0.00846774547018936"
        rpy="0 0 0" />
      <mass
        value="0.00721958973240477" />
      <inertia
        ixx="6.54404894420929E-07"
        ixy="1.22110369400717E-15"
        ixz="-6.62019872333363E-13"
        iyy="6.47825689710172E-07"
        iyz="1.54040753114242E-07"
        izz="4.21420309970185E-07" />
    </inertial>
    <visual>
      <origin
        xyz="0 0 0"
        rpy="0 0 0" />
      <geometry>
        <mesh
          filename="package://机械臂/meshes/Link12.STL" />
      </geometry>
      <material
        name="">
        <color
          rgba="1 1 1 1" />
      </material>
    </visual>
    <collision>
      <origin
        xyz="0 0 0"
        rpy="0 0 0" />
      <geometry>
        <mesh
          filename="package://机械臂/meshes/Link12.STL" />
      </geometry>
    </collision>
  </link>
  <joint
    name="joint12"
    type="revolute">
    <origin
      xyz="0 -0.090563 -0.042406"
      rpy="0 0 0" />
    <parent
      link="Link9" />
    <child
      link="Link12" />
    <axis
      xyz="1 0 0" />
    <limit
      lower="0"
      upper="0"
      effort="0"
      velocity="0" />
    <mimic
      joint="joint9"
      multiplier="1"
      offset="0" />
  </joint>
  <link
    name="Link10">
    <inertial>
      <origin
        xyz="2.73117885352114E-06 -0.0378415938959361 -0.0340631082101284"
        rpy="0 0 0" />
      <mass
        value="0.0319358848099955" />
      <inertia
        ixx="2.01086352196278E-05"
        ixy="-3.23000917392899E-09"
        ixz="-3.60995549403207E-10"
        iyy="3.47222994627157E-06"
        iyz="-3.58549758813272E-06"
        izz="2.07021101800963E-05" />
    </inertial>
    <visual>
      <origin
        xyz="0 0 0"
        rpy="0 0 0" />
      <geometry>
        <mesh
          filename="package://机械臂/meshes/Link10.STL" />
      </geometry>
      <material
        name="">
        <color
          rgba="1 1 1 1" />
      </material>
    </visual>
    <collision>
      <origin
        xyz="0 0 0"
        rpy="0 0 0" />
      <geometry>
        <mesh
          filename="package://机械臂/meshes/Link10.STL" />
      </geometry>
    </collision>
  </link>
  <joint
    name="joint10"
    type="revolute">
    <origin
      xyz="0 -0.054663 -0.030601"
      rpy="0 0 0" />
    <parent
      link="Link6" />
    <child
      link="Link10" />
    <axis
      xyz="1 0 0" />
    <limit
      lower="0"
      upper="0"
      effort="0"
      velocity="0" />
    <mimic
      joint="joint9"
      multiplier="-1"
      offset="0" />
  </joint>
</robot>